---
title: try...catch 文
slug: Web/JavaScript/Guide/Exception_Handling_Statements/try...catch_Statement
---
<h3 id="try...catch_.E6.96.87" name="try...catch_.E6.96.87">try...catch 文</h3>

<p><code>try...catch</code> 文はテストしたい文のブロックを指定し、さらに投げられるであろう例外に対する 1 つ以上の対処方法を指定します。例外が投げられると <code>try...catch</code> 文がそれを受け取ります。</p>

<p><code>try...catch</code> 文は 1 つの <code>try</code> ブロックと 0 個以上の <code>catch</code> ブロックからなります。前者は 1 つ以上の文からなります。後者は try ブロックで例外が投げられた場合にどうするかを指定する文からなります。すなわち、成功させたい <code>try</code> ブロックと、失敗した場合にコントロールを渡す <code>catch</code> ブロックからなります。<code>try</code> ブロック内（もしくは <code>try</code> ブロック内から呼び出された関数内）のいずれかの文が例外を投げた場合、コントロールはすぐに <code>catch</code> ブロックに移ります。<code>try</code> ブロックで例外が投げられなかった場合は <code>catch</code> ブロックは飛ばされます。<code>finally</code> ブロックは <code>try</code> および <code>catch</code> ブロックが実行された後に実行されます。ただし <code>try...catch</code> 文の後に続く文より先に実行されます。</p>

<p>次の例では <code>try...catch</code> 文を使用しています。この例では渡された値に基づいて配列から月の名前を取り出す関数を呼び出します。値に対応する月の数字 (1-12) がなかったら、<code>InvalidMonthNo</code> という値を持つ例外が投げられ、<code>catch</code> ブロックの中の文は <code>monthName</code> という変数に <code>unknown</code> という値をセットします。</p>

<pre>function getMonthName (mo) {
    mo=mo-1; // 月の数字を配列のインデックスに合わせる (1=Jan, 12=Dec)
    var months=new Array("Jan","Feb","Mar","Apr","May","Jun","Jul",
          "Aug","Sep","Oct","Nov","Dec");
    if (months[mo] != null) {
       return months[mo]
    } else {
       throw "InvalidMonthNo"
    }
}

try {
// テストする文
    monthName=getMonthName(myMonth) // 関数は例外を投げることがある
}
catch (e) {
    monthName="unknown"
    logMyErrors(e) // 例外オブジェクトをエラー処理部分に渡す
}
</pre>

<h4 id="catch_.E3.83.96.E3.83.AD.E3.83.83.E3.82.AF" name="catch_.E3.83.96.E3.83.AD.E3.83.83.E3.82.AF">catch ブロック</h4>

<p>単一の <code>catch</code> ブロックを使用すると、<code>try</code> ブロックで生じうるすべての例外を扱うことができます。また、扱う例外の種類によって <code>catch</code> ブロックをそれぞれに分けることもできます。</p>

<p><strong>単一の catch ブロック</strong><br>
 <code>try</code> ブロックで投げられるいかなる例外にも対応したエラー処理コードを実行するには、<code>try...catch</code> 文で <code>catch</code> を 1 つ使用してください。</p>

<p>単一の <code>catch</code> ブロックは次のように使用します。</p>

<pre>catch (catchID) {
  statements
}
</pre>

<p><code>catch</code> ブロックは、<code>throw</code> 文で指定された値を持つ識別子（上記の構文における <code>catchID</code>）を指定します。この識別子を使用することで投げられた例外についての情報を得ることができます。JavaScript は <code>catch</code> ブロックに入るときにこの識別子を作成します。識別子は <code>catch</code> ブロックにいる間だけ持続します。つまり、<code>catch</code> ブロックの実行が終了するとその識別子はもう使えなくなります。</p>

<p>例えば、次のコードは例外を投げます。例外が生じるとコントロールが <code>catch</code> ブロックに移ります。</p>

<pre>try {
   throw "myException" // 例外を生成
}
catch (e) {
// どんな例外も扱う文
   logMyErrors(e) // 例外オブジェクトをエラー処理部分に渡す
}
</pre>

<p><strong>複数の catch ブロック</strong><br>
 1 つの <code>try</code> 文に対して、複数の条件についての <code>catch</code> ブロックを使うことができます。そして、そのそれぞれがそれぞれの種類の例外を担当します。この場合、そのブロックで指定されている例外が投げられたときだけ、適切な条件の <code>catch</code> ブロックに入ることになります。すべての未指定の例外のために、すべての例外に対応した <code>catch</code> ブロックをその文の最後の catch ブロックとしてオプション的に設けることもできます。</p>

<p>例えば、次の関数は 3 つの別の関数（どこかで定義済み）を呼び出します。この関数はその引数が妥当であるかを確かめます。妥当性確認関数が確認対象の構成要素が妥当でないと決定した場合、その関数は 0 を返し、該当する例外を呼び出し元に投げさせます。</p>

<pre>function getCustInfo(name, id, email)
{
   var n, i, e;

   if (!validate_name(name))
       throw "InvalidNameException"
   else
       n = name;
       if (!validate_id(id))
          throw "InvalidIdException"
       else
          i = id;
       if (!validate_email(email))
          throw "InvalidEmailException"
       else
          e = email;
       cust = (n + " " + i + " " + e);
       return (cust);
}
</pre>

<p>おのおのの条件の <code>catch</code> ブロックは適当な例外処理部分にコントロールを渡します。</p>

<pre>try {
// 関数は 3 つの例外を投げうる
   getCustInfo("Lee", 1234, "lee@netscape.com")
}

catch (e if e == "InvalidNameException") {
// 不正な名前に対しての処理部分を呼び出す
   bad_name_handler(e)
}

catch (e if e == "InvalidIdException") {
// 不正な ID に対しての処理部分を呼び出す
   bad_id_handler(e)
}

catch (e if e == "InvalidEmailException") {
// 不正なメールアドレスに対しての処理部分を呼び出す
   bad_email_handler(e)
}

catch (e){
// 何が起きるかはわからないが、そのログをとる
   logError(e)
}
</pre>

<h4 id="finally_.E3.83.96.E3.83.AD.E3.83.83.E3.82.AF" name="finally_.E3.83.96.E3.83.AD.E3.83.83.E3.82.AF">finally ブロック</h4>

<p><code>finally</code> ブロックは、try および catch ブロックの実行が終わった後に実行される文からなります。ただし <code>try...catch</code> 文の後に続く文より前に実行されます。<code>finally</code> ブロックは例外が投げられても投げられなくても実行されます。例外が投げられた場合、<code>finally</code> ブロック内の文はたとえ例外処理をする catch ブロックがなくても実行されます。</p>

<p><code>finally</code> ブロックを使用することで、例外発生時に適切にスクリプトを停止させることができます。例えば、スクリプトで使用していたリソースを解放する必要があるかもしれません。次の例ではファイルを開き、そのファイルを使用する文を実行します（サーバサイド JavaScript ではファイルにアクセスできます）。ファイルを開いている間に例外が投げられると、スクリプトが停止する前に <code>finally</code> ブロックがそのファイルを閉じます。</p>

<pre>openMyFile();
try {
   writeMyFile(theData); // エラーを投げる可能性がある
} catch(e) {
   handleError(e); // エラーを受け取り、それを処理する
} finally {
   closeMyFile(); // 常にリソースを閉じる
}
</pre>

<h4 id="try...catch_.E6.96.87.E3.81.AE.E3.83.8D.E3.82.B9.E3.83.88" name="try...catch_.E6.96.87.E3.81.AE.E3.83.8D.E3.82.B9.E3.83.88">try...catch 文のネスト</h4>

<p>1 つ以上の <code>try...catch</code> 文を入れ子にすることができます。内側の <code>try...catch</code> 文に catch ブロックがない場合、囲んでいる <code>try...catch</code> 文の catch ブロックがマッチしているか確認されます。</p>

<p>{{ PreviousNext("JavaScript/Guide/Exception_Handling_Statements/throw_Statement", "JavaScript/Guide/Defining_Functions") }}</p>
